[   12.614062] platform regulatory.0: Direct firmware load for regulatory.db failed with error -2
[  133.183993] cloud-init[390]: 2024-10-26 15:25:15,340 - url_helper.py[WARNING]: Calling 'http://[fd00:ec2::254]/latest/api/token' failed [0/120s]: request error [HTTPConnectionPool(host='fd00:ec2::254', port=80): Max retries exceeded with url: /latest/api/token (Caused by NewConnectionError('<urllib3.connection.HTTPConnection object at 0x7fd41d0de240>: Failed to establish a new connection: [Errno 101] Network is unreachable'))]
[  134.337506] cloud-init[390]: 2024-10-26 15:25:16,493 - url_helper.py[WARNING]: Calling 'http://[fd00:ec2::254]/latest/api/token' failed [1/120s]: request error [HTTPConnectionPool(host='fd00:ec2::254', port=80): Max retries exceeded with url: /latest/api/token (Caused by NewConnectionError('<urllib3.connection.HTTPConnection object at 0x7fd41d148050>: Failed to establish a new connection: [Errno 101] Network is unreachable'))]
[  135.491251] cloud-init[390]: 2024-10-26 15:25:17,647 - url_helper.py[WARNING]: Calling 'http://[fd00:ec2::254]/latest/api/token' failed [2/120s]: request error [HTTPConnectionPool(host='fd00:ec2::254', port=80): Max retries exceeded with url: /latest/api/token (Caused by NewConnectionError('<urllib3.connection.HTTPConnection object at 0x7fd41d0dde20>: Failed to establish a new connection: [Errno 101] Network is unreachable'))]
[  136.644719] cloud-init[390]: 2024-10-26 15:25:18,800 - url_helper.py[WARNING]: Calling 'http://[fd00:ec2::254]/latest/api/token' failed [3/120s]: request error [HTTPConnectionPool(host='fd00:ec2::254', port=80): Max retries exceeded with url: /latest/api/token (Caused by NewConnectionError('<urllib3.connection.HTTPConnection object at 0x7fd41d1497c0>: Failed to establish a new connection: [Errno 101] Network is unreachable'))]
[  137.797512] cloud-init[390]: 2024-10-26 15:25:19,953 - url_helper.py[WARNING]: Calling 'http://[fd00:ec2::254]/latest/api/token' failed [4/120s]: request error [HTTPConnectionPool(host='fd00:ec2::254', port=80): Max retries exceeded with url: /latest/api/token (Caused by NewConnectionError('<urllib3.connection.HTTPConnection object at 0x7fd41d14af60>: Failed to establish a new connection: [Errno 101] Network is unreachable'))]
[  138.952338] cloud-init[390]: 2024-10-26 15:25:21,108 - url_helper.py[WARNING]: Calling 'http://[fd00:ec2::254]/latest/api/token' failed [5/120s]: request error [HTTPConnectionPool(host='fd00:ec2::254', port=80): Max retries exceeded with url: /latest/api/token (Caused by NewConnectionError('<urllib3.connection.HTTPConnection object at 0x7fd41d087950>: Failed to establish a new connection: [Errno 101] Network is unreachable'))]
[  141.106174] cloud-init[390]: 2024-10-26 15:25:23,262 - url_helper.py[WARNING]: Calling 'http://[fd00:ec2::254]/latest/api/token' failed [8/120s]: request error [HTTPConnectionPool(host='fd00:ec2::254', port=80): Max retries exceeded with url: /latest/api/token (Caused by NewConnectionError('<urllib3.connection.HTTPConnection object at 0x7fd41d0df620>: Failed to establish a new connection: [Errno 101] Network is unreachable'))]
[  143.259603] cloud-init[390]: 2024-10-26 15:25:25,415 - url_helper.py[WARNING]: Calling 'http://[fd00:ec2::254]/latest/api/token' failed [10/120s]: request error [HTTPConnectionPool(host='fd00:ec2::254', port=80): Max retries exceeded with url: /latest/api/token (Caused by NewConnectionError('<urllib3.connection.HTTPConnection object at 0x7fd41d0ddd00>: Failed to establish a new connection: [Errno 101] Network is unreachable'))]
[  145.412854] cloud-init[390]: 2024-10-26 15:25:27,568 - url_helper.py[WARNING]: Calling 'http://[fd00:ec2::254]/latest/api/token' failed [12/120s]: request error [HTTPConnectionPool(host='fd00:ec2::254', port=80): Max retries exceeded with url: /latest/api/token (Caused by NewConnectionError('<urllib3.connection.HTTPConnection object at 0x7fd41d14a270>: Failed to establish a new connection: [Errno 101] Network is unreachable'))]
[  147.567486] cloud-init[390]: 2024-10-26 15:25:29,723 - url_helper.py[WARNING]: Calling 'http://[fd00:ec2::254]/latest/api/token' failed [14/120s]: request error [HTTPConnectionPool(host='fd00:ec2::254', port=80): Max retries exceeded with url: /latest/api/token (Caused by NewConnectionError('<urllib3.connection.HTTPConnection object at 0x7fd41d14a390>: Failed to establish a new connection: [Errno 101] Network is unreachable'))]
[  149.720354] cloud-init[390]: 2024-10-26 15:25:31,876 - url_helper.py[WARNING]: Calling 'http://[fd00:ec2::254]/latest/api/token' failed [16/120s]: request error [HTTPConnectionPool(host='fd00:ec2::254', port=80): Max retries exceeded with url: /latest/api/token (Caused by NewConnectionError('<urllib3.connection.HTTPConnection object at 0x7fd41d149160>: Failed to establish a new connection: [Errno 101] Network is unreachable'))]
[  152.875122] cloud-init[390]: 2024-10-26 15:25:35,030 - url_helper.py[WARNING]: Calling 'http://[fd00:ec2::254]/latest/api/token' failed [19/120s]: request error [HTTPConnectionPool(host='fd00:ec2::254', port=80): Max retries exceeded with url: /latest/api/token (Caused by NewConnectionError('<urllib3.connection.HTTPConnection object at 0x7fd41d148d40>: Failed to establish a new connection: [Errno 101] Network is unreachable'))]
[  156.027528] cloud-init[390]: 2024-10-26 15:25:38,183 - url_helper.py[WARNING]: Calling 'http://[fd00:ec2::254]/latest/api/token' failed [22/120s]: request error [HTTPConnectionPool(host='fd00:ec2::254', port=80): Max retries exceeded with url: /latest/api/token (Caused by NewConnectionError('<urllib3.connection.HTTPConnection object at 0x7fd41ced90a0>: Failed to establish a new connection: [Errno 101] Network is unreachable'))]
[  159.181013] cloud-init[390]: 2024-10-26 15:25:41,337 - url_helper.py[WARNING]: Calling 'http://[fd00:ec2::254]/latest/api/token' failed [26/120s]: request error [HTTPConnectionPool(host='fd00:ec2::254', port=80): Max retries exceeded with url: /latest/api/token (Caused by NewConnectionError('<urllib3.connection.HTTPConnection object at 0x7fd41ced8530>: Failed to establish a new connection: [Errno 101] Network is unreachable'))]
[  162.335037] cloud-init[390]: 2024-10-26 15:25:44,490 - url_helper.py[WARNING]: Calling 'http://[fd00:ec2::254]/latest/api/token' failed [29/120s]: request error [HTTPConnectionPool(host='fd00:ec2::254', port=80): Max retries exceeded with url: /latest/api/token (Caused by NewConnectionError('<urllib3.connection.HTTPConnection object at 0x7fd41ceda900>: Failed to establish a new connection: [Errno 101] Network is unreachable'))]
[  165.488529] cloud-init[390]: 2024-10-26 15:25:47,645 - url_helper.py[WARNING]: Calling 'http://[fd00:ec2::254]/latest/api/token' failed [32/120s]: request error [HTTPConnectionPool(host='fd00:ec2::254', port=80): Max retries exceeded with url: /latest/api/token (Caused by NewConnectionError('<urllib3.connection.HTTPConnection object at 0x7fd41cefc170>: Failed to establish a new connection: [Errno 101] Network is unreachable'))]
[  169.643276] cloud-init[390]: 2024-10-26 15:25:51,799 - url_helper.py[WARNING]: Calling 'http://[fd00:ec2::254]/latest/api/token' failed [36/120s]: request error [HTTPConnectionPool(host='fd00:ec2::254', port=80): Max retries exceeded with url: /latest/api/token (Caused by NewConnectionError('<urllib3.connection.HTTPConnection object at 0x7fd41cedb230>: Failed to establish a new connection: [Errno 101] Network is unreachable'))]
[  173.797744] cloud-init[390]: 2024-10-26 15:25:55,953 - url_helper.py[WARNING]: Calling 'http://[fd00:ec2::254]/latest/api/token' failed [40/120s]: request error [HTTPConnectionPool(host='fd00:ec2::254', port=80): Max retries exceeded with url: /latest/api/token (Caused by NewConnectionError('<urllib3.connection.HTTPConnection object at 0x7fd41cefd9a0>: Failed to establish a new connection: [Errno 101] Network is unreachable'))]
[  177.951962] cloud-init[390]: 2024-10-26 15:26:00,107 - url_helper.py[WARNING]: Calling 'http://[fd00:ec2::254]/latest/api/token' failed [44/120s]: request error [HTTPConnectionPool(host='fd00:ec2::254', port=80): Max retries exceeded with url: /latest/api/token (Caused by NewConnectionError('<urllib3.connection.HTTPConnection object at 0x7fd41cefd5e0>: Failed to establish a new connection: [Errno 101] Network is unreachable'))]
[  182.105550] cloud-init[390]: 2024-10-26 15:26:04,260 - url_helper.py[WARNING]: Calling 'http://[fd00:ec2::254]/latest/api/token' failed [49/120s]: request error [HTTPConnectionPool(host='fd00:ec2::254', port=80): Max retries exceeded with url: /latest/api/token (Caused by NewConnectionError('<urllib3.connection.HTTPConnection object at 0x7fd41ceff560>: Failed to establish a new connection: [Errno 101] Network is unreachable'))]
[  186.260315] cloud-init[390]: 2024-10-26 15:26:08,416 - url_helper.py[WARNING]: Calling 'http://[fd00:ec2::254]/latest/api/token' failed [53/120s]: request error [HTTPConnectionPool(host='fd00:ec2::254', port=80): Max retries exceeded with url: /latest/api/token (Caused by NewConnectionError('<urllib3.connection.HTTPConnection object at 0x7fd41cf28dd0>: Failed to establish a new connection: [Errno 101] Network is unreachable'))]
[  191.414103] cloud-init[390]: 2024-10-26 15:26:13,570 - url_helper.py[WARNING]: Calling 'http://[fd00:ec2::254]/latest/api/token' failed [58/120s]: request error [HTTPConnectionPool(host='fd00:ec2::254', port=80): Max retries exceeded with url: /latest/api/token (Caused by NewConnectionError('<urllib3.connection.HTTPConnection object at 0x7fd41ceff7d0>: Failed to establish a new connection: [Errno 101] Network is unreachable'))]
[  196.576922] cloud-init[390]: 2024-10-26 15:26:18,732 - url_helper.py[WARNING]: Calling 'http://[fd00:ec2::254]/latest/api/token' failed [63/120s]: request error [HTTPConnectionPool(host='fd00:ec2::254', port=80): Max retries exceeded with url: /latest/api/token (Caused by NewConnectionError('<urllib3.connection.HTTPConnection object at 0x7fd41cf2a7e0>: Failed to establish a new connection: [Errno 101] Network is unreachable'))]
[  201.729899] cloud-init[390]: 2024-10-26 15:26:23,885 - url_helper.py[WARNING]: Calling 'http://[fd00:ec2::254]/latest/api/token' failed [68/120s]: request error [HTTPConnectionPool(host='fd00:ec2::254', port=80): Max retries exceeded with url: /latest/api/token (Caused by NewConnectionError('<urllib3.connection.HTTPConnection object at 0x7fd41cf28bf0>: Failed to establish a new connection: [Errno 101] Network is unreachable'))]
[  206.884296] cloud-init[390]: 2024-10-26 15:26:29,039 - url_helper.py[WARNING]: Calling 'http://[fd00:ec2::254]/latest/api/token' failed [73/120s]: request error [HTTPConnectionPool(host='fd00:ec2::254', port=80): Max retries exceeded with url: /latest/api/token (Caused by NewConnectionError('<urllib3.connection.HTTPConnection object at 0x7fd41cf500b0>: Failed to establish a new connection: [Errno 101] Network is unreachable'))]
[  212.037963] cloud-init[390]: 2024-10-26 15:26:34,194 - url_helper.py[WARNING]: Calling 'http://[fd00:ec2::254]/latest/api/token' failed [79/120s]: request error [HTTPConnectionPool(host='fd00:ec2::254', port=80): Max retries exceeded with url: /latest/api/token (Caused by NewConnectionError('<urllib3.connection.HTTPConnection object at 0x7fd41cf284a0>: Failed to establish a new connection: [Errno 101] Network is unreachable'))]
[  218.193204] cloud-init[390]: 2024-10-26 15:26:40,349 - url_helper.py[WARNING]: Calling 'http://[fd00:ec2::254]/latest/api/token' failed [85/120s]: request error [HTTPConnectionPool(host='fd00:ec2::254', port=80): Max retries exceeded with url: /latest/api/token (Caused by NewConnectionError('<urllib3.connection.HTTPConnection object at 0x7fd41cf518e0>: Failed to establish a new connection: [Errno 101] Network is unreachable'))]
[  224.345980] cloud-init[390]: 2024-10-26 15:26:46,502 - url_helper.py[WARNING]: Calling 'http://[fd00:ec2::254]/latest/api/token' failed [91/120s]: request error [HTTPConnectionPool(host='fd00:ec2::254', port=80): Max retries exceeded with url: /latest/api/token (Caused by NewConnectionError('<urllib3.connection.HTTPConnection object at 0x7fd41cf2a2a0>: Failed to establish a new connection: [Errno 101] Network is unreachable'))]
[  230.499770] cloud-init[390]: 2024-10-26 15:26:52,655 - url_helper.py[WARNING]: Calling 'http://[fd00:ec2::254]/latest/api/token' failed [97/120s]: request error [HTTPConnectionPool(host='fd00:ec2::254', port=80): Max retries exceeded with url: /latest/api/token (Caused by NewConnectionError('<urllib3.connection.HTTPConnection object at 0x7fd41cf2acf0>: Failed to establish a new connection: [Errno 101] Network is unreachable'))]
[  236.653304] cloud-init[390]: 2024-10-26 15:26:58,809 - url_helper.py[WARNING]: Calling 'http://[fd00:ec2::254]/latest/api/token' failed [103/120s]: request error [HTTPConnectionPool(host='fd00:ec2::254', port=80): Max retries exceeded with url: /latest/api/token (Caused by NewConnectionError('<urllib3.connection.HTTPConnection object at 0x7fd41cf28920>: Failed to establish a new connection: [Errno 101] Network is unreachable'))]
[  242.807682] cloud-init[390]: 2024-10-26 15:27:04,963 - url_helper.py[WARNING]: Calling 'http://[fd00:ec2::254]/latest/api/token' failed [109/120s]: request error [HTTPConnectionPool(host='fd00:ec2::254', port=80): Max retries exceeded with url: /latest/api/token (Caused by NewConnectionError('<urllib3.connection.HTTPConnection object at 0x7fd41cefd3d0>: Failed to establish a new connection: [Errno 101] Network is unreachable'))]
[  249.961041] cloud-init[390]: 2024-10-26 15:27:12,116 - url_helper.py[WARNING]: Calling 'http://[fd00:ec2::254]/latest/api/token' failed [116/120s]: request error [HTTPConnectionPool(host='fd00:ec2::254', port=80): Max retries exceeded with url: /latest/api/token (Caused by NewConnectionError('<urllib3.connection.HTTPConnection object at 0x7fd41cf29d00>: Failed to establish a new connection: [Errno 101] Network is unreachable'))]
